<?xml version="1.0" encoding="utf-8"?>
<!-- This URDF was automatically created by SolidWorks to URDF Exporter! Originally created by Stephen Brawner (brawner@gmail.com) 
     Commit Version: 1.6.0-4-g7f85cfe  Build Version: 1.6.7995.38578
     For more information, please see http://wiki.ros.org/sw_urdf_exporter -->
<robot
  name="arm">
  <link
    name="base_link">
    <inertial>
      <origin
        xyz="0.0298589218198961 -0.289459135628351 0.00349838519341539"
        rpy="0 0 0" />
      <mass
        value="5.83773534684926" />
      <inertia
        ixx="0.272242796761267"
        ixy="0.0840840133459402"
        ixz="0.000602827819831489"
        iyy="0.0819087217960493"
        iyz="0.000661975917566431"
        izz="0.333557134093876" />
    </inertial>
    <visual>
      <origin
        xyz="0 0 0"
        rpy="0 0 0" />
      <geometry>
        <mesh
          filename="package://arm/meshes/base_link.STL" />
      </geometry>
      <material
        name="">
        <color
          rgba="1 1 1 1" />
      </material>
    </visual>
    <collision>
      <origin
        xyz="0 0 0"
        rpy="0 0 0" />
      <geometry>
        <mesh
          filename="package://arm/meshes/base_link.STL" />
      </geometry>
    </collision>
  </link>
  <link
    name="link1">
    <inertial>
      <origin
        xyz="-0.0298589218198977 -0.00349838519341611 0.242459135628349"
        rpy="0 0 0" />
      <mass
        value="5.83773534684926" />
      <inertia
        ixx="0.27224279676126"
        ixy="0.000602827819829954"
        ixz="0.0840840133459392"
        iyy="0.333557134093868"
        iyz="0.000661975917568578"
        izz="0.081908721796048" />
    </inertial>
    <visual>
      <origin
        xyz="0 0 0"
        rpy="0 0 0" />
      <geometry>
        <mesh
          filename="package://arm/meshes/link1.STL" />
      </geometry>
      <material
        name="">
        <color
          rgba="1 1 1 1" />
      </material>
    </visual>
    <collision>
      <origin
        xyz="0 0 0"
        rpy="0 0 0" />
      <geometry>
        <mesh
          filename="package://arm/meshes/link1.STL" />
      </geometry>
    </collision>
  </link>
  <joint
    name="joint1"
    type="revolute">
    <origin
      xyz="0 -0.047 0"
      rpy="-1.5708 0 3.1416" />
    <parent
      link="base_link" />
    <child
      link="link1" />
    <axis
      xyz="0 0 1" />
    <limit
      lower="-2.1"
      upper="2.1"
      effort="0"
      velocity="0" />
  </joint>
  <link
    name="link2">
    <inertial>
      <origin
        xyz="-0.0221686427482291 0.00349838519341531 0.0398439270052678"
        rpy="0 0 0" />
      <mass
        value="5.83773534684926" />
      <inertia
        ixx="0.158221740998495"
        ixy="0.000828233142214561"
        ixz="0.125584283723192"
        iyy="0.333557134093868"
        iyz="0.000340063755696033"
        izz="0.195929777558813" />
    </inertial>
    <visual>
      <origin
        xyz="0 0 0"
        rpy="0 0 0" />
      <geometry>
        <mesh
          filename="package://arm/meshes/link2.STL" />
      </geometry>
      <material
        name="">
        <color
          rgba="1 1 1 1" />
      </material>
    </visual>
    <collision>
      <origin
        xyz="0 0 0"
        rpy="0 0 0" />
      <geometry>
        <mesh
          filename="package://arm/meshes/link2.STL" />
      </geometry>
    </collision>
  </link>
  <joint
    name="joint2"
    type="revolute">
    <origin
      xyz="0 0 0.208"
      rpy="0 1.2217 -3.1416" />
    <parent
      link="link1" />
    <child
      link="link2" />
    <axis
      xyz="0 -1 0" />
    <limit
      lower="-1.3"
      upper="1.046"
      effort="0"
      velocity="0" />
  </joint>
  <link
    name="link3">
    <inertial>
      <origin
        xyz="-0.0034983851934161 0.225540864371653 0.029858921819878"
        rpy="0 0 0" />
      <mass
        value="5.83773534684926" />
      <inertia
        ixx="0.333557134093868"
        ixy="-0.000661975917568616"
        ixz="-0.000602827819829908"
        iyy="0.0819087217960627"
        iyz="0.0840840133459558"
        izz="0.272242796761245" />
    </inertial>
    <visual>
      <origin
        xyz="0 0 0"
        rpy="0 0 0" />
      <geometry>
        <mesh
          filename="package://arm/meshes/link3.STL" />
      </geometry>
      <material
        name="">
        <color
          rgba="1 1 1 1" />
      </material>
    </visual>
    <collision>
      <origin
        xyz="0 0 0"
        rpy="0 0 0" />
      <geometry>
        <mesh
          filename="package://arm/meshes/link3.STL" />
      </geometry>
    </collision>
  </link>
  <joint
    name="joint3"
    type="revolute">
    <origin
      xyz="-0.24432 0 0.088925"
      rpy="-0.34907 0 -1.5708" />
    <parent
      link="link2" />
    <child
      link="link3" />
    <axis
      xyz="1 0 0" />
    <limit
      lower="-0.61"
      upper="2.965"
      effort="0"
      velocity="0" />
  </joint>
  <link
    name="link4">
    <inertial>
      <origin
        xyz="-0.250540864371647 0.00344838519341907 0.00664107818009065"
        rpy="0 0 0" />
      <mass
        value="5.83773534684926" />
      <inertia
        ixx="0.081908721796048"
        ixy="-0.000661975917566328"
        ixz="0.0840840133459392"
        iyy="0.333557134093868"
        iyz="-0.000602827819831595"
        izz="0.27224279676126" />
    </inertial>
    <visual>
      <origin
        xyz="0 0 0"
        rpy="0 0 0" />
      <geometry>
        <mesh
          filename="package://arm/meshes/link4.STL" />
      </geometry>
      <material
        name="">
        <color
          rgba="1 1 1 1" />
      </material>
    </visual>
    <collision>
      <origin
        xyz="0 0 0"
        rpy="0 0 0" />
      <geometry>
        <mesh
          filename="package://arm/meshes/link4.STL" />
      </geometry>
    </collision>
  </link>
  <joint
    name="joint4"
    type="revolute">
    <origin
      xyz="-5E-05 -0.025 0.0365"
      rpy="-3.1416 0 -1.5708" />
    <parent
      link="link3" />
    <child
      link="link4" />
    <axis
      xyz="0 0 1" />
    <limit
      lower="-3.14"
      upper="3.14"
      effort="0"
      velocity="0" />
  </joint>
  <link
    name="link5">
    <inertial>
      <origin
        xyz="0.250141078180099 0.00344838519341863 0.25054086437167"
        rpy="0 0 0" />
      <mass
        value="5.83773534684926" />
      <inertia
        ixx="0.27224279676126"
        ixy="-0.000602827819829894"
        ixz="-0.0840840133459392"
        iyy="0.333557134093868"
        iyz="0.000661975917568661"
        izz="0.081908721796048" />
    </inertial>
    <visual>
      <origin
        xyz="0 0 0"
        rpy="0 0 0" />
      <geometry>
        <mesh
          filename="package://arm/meshes/link5.STL" />
      </geometry>
      <material
        name="">
        <color
          rgba="1 1 1 1" />
      </material>
    </visual>
    <collision>
      <origin
        xyz="0 0 0"
        rpy="0 0 0" />
      <geometry>
        <mesh
          filename="package://arm/meshes/link5.STL" />
      </geometry>
    </collision>
  </link>
  <joint
    name="joint5"
    type="revolute">
    <origin
      xyz="0 0 -0.2435"
      rpy="3.1416 -1.5708 0" />
    <parent
      link="link4" />
    <child
      link="link5" />
    <axis
      xyz="0 1 0" />
    <limit
      lower="-1.919"
      upper="1.919"
      effort="0"
      velocity="0" />
  </joint>
  <link
    name="link6">
    <inertial>
      <origin
        xyz="0.283641078180096 0.218698945828686 0.122284043006308"
        rpy="0 0 0" />
      <mass
        value="5.83773534684926" />
      <inertia
        ixx="0.27224279676126"
        ixy="-0.0731203055196466"
        ixz="-0.0415199424668908"
        iyy="0.145394112831817"
        iyz="-0.109297946894754"
        izz="0.270071743058099" />
    </inertial>
    <visual>
      <origin
        xyz="0 0 0"
        rpy="0 0 0" />
      <geometry>
        <mesh
          filename="package://arm/meshes/link6.STL" />
      </geometry>
      <material
        name="">
        <color
          rgba="1 1 1 1" />
      </material>
    </visual>
    <collision>
      <origin
        xyz="0 0 0"
        rpy="0 0 0" />
      <geometry>
        <mesh
          filename="package://arm/meshes/link6.STL" />
      </geometry>
    </collision>
  </link>
  <joint
    name="joint6"
    type="revolute">
    <origin
      xyz="-0.0335 0 0"
      rpy="0 0 0" />
    <parent
      link="link5" />
    <child
      link="link6" />
    <axis
      xyz="1 0 0" />
    <limit
      lower="-3.14"
      upper="3.14"
      effort="0"
      velocity="0" />
  </joint>
</robot>